[2021-12-22 21:10:23,789] {taskinstance.py:1035} INFO - Dependencies all met for <TaskInstance: data_pipeline1.face_crop scheduled__2021-12-20T00:53:00+00:00 [queued]>
[2021-12-22 21:10:23,792] {taskinstance.py:1035} INFO - Dependencies all met for <TaskInstance: data_pipeline1.face_crop scheduled__2021-12-20T00:53:00+00:00 [queued]>
[2021-12-22 21:10:23,792] {taskinstance.py:1241} INFO - 
--------------------------------------------------------------------------------
[2021-12-22 21:10:23,792] {taskinstance.py:1242} INFO - Starting attempt 4 of 6
[2021-12-22 21:10:23,792] {taskinstance.py:1243} INFO - 
--------------------------------------------------------------------------------
[2021-12-22 21:10:23,801] {taskinstance.py:1262} INFO - Executing <Task(BashOperator): face_crop> on 2021-12-20 00:53:00+00:00
[2021-12-22 21:10:23,805] {standard_task_runner.py:52} INFO - Started process 46264 to run task
[2021-12-22 21:10:23,809] {standard_task_runner.py:76} INFO - Running: ['airflow', 'tasks', 'run', 'data_pipeline1', 'face_crop', 'scheduled__2021-12-20T00:53:00+00:00', '--job-id', '330', '--raw', '--subdir', '/home/myamya/project/dockers/airflow/dags/hello_world.py', '--cfg-path', '/tmp/tmpcy7fkx6c', '--error-file', '/tmp/tmpn1i8fogn']
[2021-12-22 21:10:23,810] {standard_task_runner.py:77} INFO - Job 330: Subtask face_crop
[2021-12-22 21:10:23,827] {logging_mixin.py:109} INFO - Running <TaskInstance: data_pipeline1.face_crop scheduled__2021-12-20T00:53:00+00:00 [running]> on host myamya
[2021-12-22 21:10:23,860] {taskinstance.py:1412} INFO - Exporting the following env vars:
AIRFLOW_CTX_DAG_OWNER=yangjae
AIRFLOW_CTX_DAG_ID=data_pipeline1
AIRFLOW_CTX_TASK_ID=face_crop
AIRFLOW_CTX_EXECUTION_DATE=2021-12-20T00:53:00+00:00
AIRFLOW_CTX_DAG_RUN_ID=scheduled__2021-12-20T00:53:00+00:00
[2021-12-22 21:10:23,860] {subprocess.py:62} INFO - Tmp dir root location: 
 /tmp
[2021-12-22 21:10:23,861] {subprocess.py:74} INFO - Running command: ['bash', '-c', 'docker run -it -v /home/myamya/project/image_files/:/home/myamya/project/image_files/ google_api:0.8 /bin/bash init.sh ']
[2021-12-22 21:10:23,866] {subprocess.py:85} INFO - Output:
[2021-12-22 21:10:24,639] {subprocess.py:89} INFO - 0
[2021-12-22 21:10:24,639] {subprocess.py:89} INFO - 2
[2021-12-22 21:10:24,639] {subprocess.py:89} INFO - 3
[2021-12-22 21:10:24,639] {subprocess.py:89} INFO - Traceback (most recent call last):
[2021-12-22 21:10:24,639] {subprocess.py:89} INFO -   File "/home/myamya/project/google_vision_api.py", line 514, in <module>
[2021-12-22 21:10:24,639] {subprocess.py:89} INFO -     main(sys.argv)
[2021-12-22 21:10:24,639] {subprocess.py:89} INFO -   File "/home/myamya/project/google_vision_api.py", line 500, in main
[2021-12-22 21:10:24,639] {subprocess.py:89} INFO -     detector.crop_faces_rootdir(srcdir, desdir, maxnum)
[2021-12-22 21:10:24,639] {subprocess.py:89} INFO -   File "/home/myamya/project/google_vision_api.py", line 466, in crop_faces_rootdir
[2021-12-22 21:10:24,639] {subprocess.py:89} INFO -     self.crop_faces_dir(os.path.join(src_dir), des_dir,maxnum)
[2021-12-22 21:10:24,640] {subprocess.py:89} INFO -   File "/home/myamya/project/google_vision_api.py", line 428, in crop_faces_dir
[2021-12-22 21:10:24,640] {subprocess.py:89} INFO -     annotation_file.write("%s" %(new_face_ann))
[2021-12-22 21:10:24,640] {subprocess.py:89} INFO - UnboundLocalError: local variable 'new_face_ann' referenced before assignment
[2021-12-22 21:10:24,865] {subprocess.py:93} INFO - Command exited with return code 1
[2021-12-22 21:10:24,866] {taskinstance.py:1686} ERROR - Task failed with exception
Traceback (most recent call last):
  File "/home/myamya/anaconda3/lib/python3.9/site-packages/airflow/models/taskinstance.py", line 1324, in _run_raw_task
    self._execute_task_with_callbacks(context)
  File "/home/myamya/anaconda3/lib/python3.9/site-packages/airflow/models/taskinstance.py", line 1443, in _execute_task_with_callbacks
    result = self._execute_task(context, self.task)
  File "/home/myamya/anaconda3/lib/python3.9/site-packages/airflow/models/taskinstance.py", line 1499, in _execute_task
    result = execute_callable(context=context)
  File "/home/myamya/anaconda3/lib/python3.9/site-packages/airflow/operators/bash.py", line 187, in execute
    raise AirflowException(
airflow.exceptions.AirflowException: Bash command failed. The command returned a non-zero exit code 1.
[2021-12-22 21:10:24,873] {taskinstance.py:1270} INFO - Marking task as UP_FOR_RETRY. dag_id=data_pipeline1, task_id=face_crop, execution_date=20211220T005300, start_date=20211222T121023, end_date=20211222T121024
[2021-12-22 21:10:24,889] {standard_task_runner.py:88} ERROR - Failed to execute job 330 for task face_crop
Traceback (most recent call last):
  File "/home/myamya/anaconda3/lib/python3.9/site-packages/airflow/task/task_runner/standard_task_runner.py", line 85, in _start_by_fork
    args.func(args, dag=self.dag)
  File "/home/myamya/anaconda3/lib/python3.9/site-packages/airflow/cli/cli_parser.py", line 48, in command
    return func(*args, **kwargs)
  File "/home/myamya/anaconda3/lib/python3.9/site-packages/airflow/utils/cli.py", line 92, in wrapper
    return f(*args, **kwargs)
  File "/home/myamya/anaconda3/lib/python3.9/site-packages/airflow/cli/commands/task_command.py", line 292, in task_run
    _run_task_by_selected_method(args, dag, ti)
  File "/home/myamya/anaconda3/lib/python3.9/site-packages/airflow/cli/commands/task_command.py", line 107, in _run_task_by_selected_method
    _run_raw_task(args, ti)
  File "/home/myamya/anaconda3/lib/python3.9/site-packages/airflow/cli/commands/task_command.py", line 180, in _run_raw_task
    ti._run_raw_task(
  File "/home/myamya/anaconda3/lib/python3.9/site-packages/airflow/utils/session.py", line 70, in wrapper
    return func(*args, session=session, **kwargs)
  File "/home/myamya/anaconda3/lib/python3.9/site-packages/airflow/models/taskinstance.py", line 1324, in _run_raw_task
    self._execute_task_with_callbacks(context)
  File "/home/myamya/anaconda3/lib/python3.9/site-packages/airflow/models/taskinstance.py", line 1443, in _execute_task_with_callbacks
    result = self._execute_task(context, self.task)
  File "/home/myamya/anaconda3/lib/python3.9/site-packages/airflow/models/taskinstance.py", line 1499, in _execute_task
    result = execute_callable(context=context)
  File "/home/myamya/anaconda3/lib/python3.9/site-packages/airflow/operators/bash.py", line 187, in execute
    raise AirflowException(
airflow.exceptions.AirflowException: Bash command failed. The command returned a non-zero exit code 1.
[2021-12-22 21:10:24,903] {local_task_job.py:154} INFO - Task exited with return code 1
[2021-12-22 21:10:24,942] {local_task_job.py:264} INFO - 0 downstream tasks scheduled from follow-on schedule check
