[2021-12-21 23:04:20,272] {taskinstance.py:1035} INFO - Dependencies all met for <TaskInstance: data_pipeline.move_file scheduled__2021-12-19T00:16:00+00:00 [queued]>
[2021-12-21 23:04:20,276] {taskinstance.py:1035} INFO - Dependencies all met for <TaskInstance: data_pipeline.move_file scheduled__2021-12-19T00:16:00+00:00 [queued]>
[2021-12-21 23:04:20,276] {taskinstance.py:1241} INFO - 
--------------------------------------------------------------------------------
[2021-12-21 23:04:20,276] {taskinstance.py:1242} INFO - Starting attempt 1 of 4
[2021-12-21 23:04:20,276] {taskinstance.py:1243} INFO - 
--------------------------------------------------------------------------------
[2021-12-21 23:04:20,285] {taskinstance.py:1262} INFO - Executing <Task(BashOperator): move_file> on 2021-12-19 00:16:00+00:00
[2021-12-21 23:04:20,287] {standard_task_runner.py:52} INFO - Started process 103976 to run task
[2021-12-21 23:04:20,288] {standard_task_runner.py:76} INFO - Running: ['airflow', 'tasks', 'run', 'data_pipeline', 'move_file', 'scheduled__2021-12-19T00:16:00+00:00', '--job-id', '173', '--raw', '--subdir', '/home/myamya/project/dockers/airflow/dags/hello_world.py', '--cfg-path', '/tmp/tmp0i2xsoi8', '--error-file', '/tmp/tmpziyoow99']
[2021-12-21 23:04:20,289] {standard_task_runner.py:77} INFO - Job 173: Subtask move_file
[2021-12-21 23:04:20,306] {logging_mixin.py:109} INFO - Running <TaskInstance: data_pipeline.move_file scheduled__2021-12-19T00:16:00+00:00 [running]> on host myamya
[2021-12-21 23:04:20,328] {taskinstance.py:1412} INFO - Exporting the following env vars:
AIRFLOW_CTX_DAG_OWNER=yangjae
AIRFLOW_CTX_DAG_ID=data_pipeline
AIRFLOW_CTX_TASK_ID=move_file
AIRFLOW_CTX_EXECUTION_DATE=2021-12-19T00:16:00+00:00
AIRFLOW_CTX_DAG_RUN_ID=scheduled__2021-12-19T00:16:00+00:00
[2021-12-21 23:04:20,328] {subprocess.py:62} INFO - Tmp dir root location: 
 /tmp
[2021-12-21 23:04:20,328] {subprocess.py:74} INFO - Running command: ['bash', '-c', 'cp /home/myamya/project/image_files/cropped_512_image/* /home/myamya/project/images/real/ | cp /home/myamya/project/image_files/sketched2/* /home/myamya/project/images/sketch/']
[2021-12-21 23:04:20,332] {subprocess.py:85} INFO - Output:
[2021-12-21 23:04:20,334] {subprocess.py:89} INFO - cp: 일반 파일 '/home/myamya/project/images/real/1_out.jpeg'을(를) 생성할 수 없음cp: 일반 파일 '/home/myamya/project/images/sketch/1_out.jpeg'을(를) 생성할 수 없음: 허가 거부: 허가 거부
[2021-12-21 23:04:20,334] {subprocess.py:89} INFO - 
[2021-12-21 23:04:20,334] {subprocess.py:93} INFO - Command exited with return code 1
[2021-12-21 23:04:20,335] {taskinstance.py:1686} ERROR - Task failed with exception
Traceback (most recent call last):
  File "/home/myamya/anaconda3/lib/python3.9/site-packages/airflow/models/taskinstance.py", line 1324, in _run_raw_task
    self._execute_task_with_callbacks(context)
  File "/home/myamya/anaconda3/lib/python3.9/site-packages/airflow/models/taskinstance.py", line 1443, in _execute_task_with_callbacks
    result = self._execute_task(context, self.task)
  File "/home/myamya/anaconda3/lib/python3.9/site-packages/airflow/models/taskinstance.py", line 1499, in _execute_task
    result = execute_callable(context=context)
  File "/home/myamya/anaconda3/lib/python3.9/site-packages/airflow/operators/bash.py", line 187, in execute
    raise AirflowException(
airflow.exceptions.AirflowException: Bash command failed. The command returned a non-zero exit code 1.
[2021-12-21 23:04:20,342] {taskinstance.py:1270} INFO - Marking task as UP_FOR_RETRY. dag_id=data_pipeline, task_id=move_file, execution_date=20211219T001600, start_date=20211221T140420, end_date=20211221T140420
[2021-12-21 23:04:20,353] {standard_task_runner.py:88} ERROR - Failed to execute job 173 for task move_file
Traceback (most recent call last):
  File "/home/myamya/anaconda3/lib/python3.9/site-packages/airflow/task/task_runner/standard_task_runner.py", line 85, in _start_by_fork
    args.func(args, dag=self.dag)
  File "/home/myamya/anaconda3/lib/python3.9/site-packages/airflow/cli/cli_parser.py", line 48, in command
    return func(*args, **kwargs)
  File "/home/myamya/anaconda3/lib/python3.9/site-packages/airflow/utils/cli.py", line 92, in wrapper
    return f(*args, **kwargs)
  File "/home/myamya/anaconda3/lib/python3.9/site-packages/airflow/cli/commands/task_command.py", line 292, in task_run
    _run_task_by_selected_method(args, dag, ti)
  File "/home/myamya/anaconda3/lib/python3.9/site-packages/airflow/cli/commands/task_command.py", line 107, in _run_task_by_selected_method
    _run_raw_task(args, ti)
  File "/home/myamya/anaconda3/lib/python3.9/site-packages/airflow/cli/commands/task_command.py", line 180, in _run_raw_task
    ti._run_raw_task(
  File "/home/myamya/anaconda3/lib/python3.9/site-packages/airflow/utils/session.py", line 70, in wrapper
    return func(*args, session=session, **kwargs)
  File "/home/myamya/anaconda3/lib/python3.9/site-packages/airflow/models/taskinstance.py", line 1324, in _run_raw_task
    self._execute_task_with_callbacks(context)
  File "/home/myamya/anaconda3/lib/python3.9/site-packages/airflow/models/taskinstance.py", line 1443, in _execute_task_with_callbacks
    result = self._execute_task(context, self.task)
  File "/home/myamya/anaconda3/lib/python3.9/site-packages/airflow/models/taskinstance.py", line 1499, in _execute_task
    result = execute_callable(context=context)
  File "/home/myamya/anaconda3/lib/python3.9/site-packages/airflow/operators/bash.py", line 187, in execute
    raise AirflowException(
airflow.exceptions.AirflowException: Bash command failed. The command returned a non-zero exit code 1.
[2021-12-21 23:04:20,380] {local_task_job.py:154} INFO - Task exited with return code 1
[2021-12-21 23:04:20,393] {local_task_job.py:264} INFO - 0 downstream tasks scheduled from follow-on schedule check
