[2021-12-21 22:16:57,309] {taskinstance.py:1035} INFO - Dependencies all met for <TaskInstance: data_pipeline.face_crop scheduled__2021-12-19T00:03:00+00:00 [queued]>
[2021-12-21 22:16:57,312] {taskinstance.py:1035} INFO - Dependencies all met for <TaskInstance: data_pipeline.face_crop scheduled__2021-12-19T00:03:00+00:00 [queued]>
[2021-12-21 22:16:57,313] {taskinstance.py:1241} INFO - 
--------------------------------------------------------------------------------
[2021-12-21 22:16:57,313] {taskinstance.py:1242} INFO - Starting attempt 3 of 4
[2021-12-21 22:16:57,313] {taskinstance.py:1243} INFO - 
--------------------------------------------------------------------------------
[2021-12-21 22:16:57,321] {taskinstance.py:1262} INFO - Executing <Task(BashOperator): face_crop> on 2021-12-19 00:03:00+00:00
[2021-12-21 22:16:57,323] {standard_task_runner.py:52} INFO - Started process 94373 to run task
[2021-12-21 22:16:57,325] {standard_task_runner.py:76} INFO - Running: ['airflow', 'tasks', 'run', 'data_pipeline', 'face_crop', 'scheduled__2021-12-19T00:03:00+00:00', '--job-id', '53', '--raw', '--subdir', '/home/myamya/project/dockers/airflow/dags/hello_world.py', '--cfg-path', '/tmp/tmpxq6_f2dt', '--error-file', '/tmp/tmpnfmyipae']
[2021-12-21 22:16:57,325] {standard_task_runner.py:77} INFO - Job 53: Subtask face_crop
[2021-12-21 22:16:57,343] {logging_mixin.py:109} INFO - Running <TaskInstance: data_pipeline.face_crop scheduled__2021-12-19T00:03:00+00:00 [running]> on host myamya
[2021-12-21 22:16:57,365] {taskinstance.py:1412} INFO - Exporting the following env vars:
AIRFLOW_CTX_DAG_OWNER=yangjae
AIRFLOW_CTX_DAG_ID=data_pipeline
AIRFLOW_CTX_TASK_ID=face_crop
AIRFLOW_CTX_EXECUTION_DATE=2021-12-19T00:03:00+00:00
AIRFLOW_CTX_DAG_RUN_ID=scheduled__2021-12-19T00:03:00+00:00
[2021-12-21 22:16:57,365] {subprocess.py:62} INFO - Tmp dir root location: 
 /tmp
[2021-12-21 22:16:57,365] {subprocess.py:74} INFO - Running command: ['bash', '-c', 'docker run -it -v /home/myamya/project/image_files/:/home/myamya/project/image_files/ google_api:0.8 /bin/bash init.sh ']
[2021-12-21 22:16:57,369] {subprocess.py:85} INFO - Output:
[2021-12-21 22:16:57,386] {subprocess.py:89} INFO - docker: Got permission denied while trying to connect to the Docker daemon socket at unix:///var/run/docker.sock: Post "http://%2Fvar%2Frun%2Fdocker.sock/v1.24/containers/create": dial unix /var/run/docker.sock: connect: permission denied.
[2021-12-21 22:16:57,387] {subprocess.py:89} INFO - See 'docker run --help'.
[2021-12-21 22:16:57,388] {subprocess.py:93} INFO - Command exited with return code 126
[2021-12-21 22:16:57,389] {taskinstance.py:1686} ERROR - Task failed with exception
Traceback (most recent call last):
  File "/home/myamya/anaconda3/lib/python3.9/site-packages/airflow/models/taskinstance.py", line 1324, in _run_raw_task
    self._execute_task_with_callbacks(context)
  File "/home/myamya/anaconda3/lib/python3.9/site-packages/airflow/models/taskinstance.py", line 1443, in _execute_task_with_callbacks
    result = self._execute_task(context, self.task)
  File "/home/myamya/anaconda3/lib/python3.9/site-packages/airflow/models/taskinstance.py", line 1499, in _execute_task
    result = execute_callable(context=context)
  File "/home/myamya/anaconda3/lib/python3.9/site-packages/airflow/operators/bash.py", line 187, in execute
    raise AirflowException(
airflow.exceptions.AirflowException: Bash command failed. The command returned a non-zero exit code 126.
[2021-12-21 22:16:57,393] {taskinstance.py:1270} INFO - Marking task as UP_FOR_RETRY. dag_id=data_pipeline, task_id=face_crop, execution_date=20211219T000300, start_date=20211221T131657, end_date=20211221T131657
[2021-12-21 22:16:57,402] {standard_task_runner.py:88} ERROR - Failed to execute job 53 for task face_crop
Traceback (most recent call last):
  File "/home/myamya/anaconda3/lib/python3.9/site-packages/airflow/task/task_runner/standard_task_runner.py", line 85, in _start_by_fork
    args.func(args, dag=self.dag)
  File "/home/myamya/anaconda3/lib/python3.9/site-packages/airflow/cli/cli_parser.py", line 48, in command
    return func(*args, **kwargs)
  File "/home/myamya/anaconda3/lib/python3.9/site-packages/airflow/utils/cli.py", line 92, in wrapper
    return f(*args, **kwargs)
  File "/home/myamya/anaconda3/lib/python3.9/site-packages/airflow/cli/commands/task_command.py", line 292, in task_run
    _run_task_by_selected_method(args, dag, ti)
  File "/home/myamya/anaconda3/lib/python3.9/site-packages/airflow/cli/commands/task_command.py", line 107, in _run_task_by_selected_method
    _run_raw_task(args, ti)
  File "/home/myamya/anaconda3/lib/python3.9/site-packages/airflow/cli/commands/task_command.py", line 180, in _run_raw_task
    ti._run_raw_task(
  File "/home/myamya/anaconda3/lib/python3.9/site-packages/airflow/utils/session.py", line 70, in wrapper
    return func(*args, session=session, **kwargs)
  File "/home/myamya/anaconda3/lib/python3.9/site-packages/airflow/models/taskinstance.py", line 1324, in _run_raw_task
    self._execute_task_with_callbacks(context)
  File "/home/myamya/anaconda3/lib/python3.9/site-packages/airflow/models/taskinstance.py", line 1443, in _execute_task_with_callbacks
    result = self._execute_task(context, self.task)
  File "/home/myamya/anaconda3/lib/python3.9/site-packages/airflow/models/taskinstance.py", line 1499, in _execute_task
    result = execute_callable(context=context)
  File "/home/myamya/anaconda3/lib/python3.9/site-packages/airflow/operators/bash.py", line 187, in execute
    raise AirflowException(
airflow.exceptions.AirflowException: Bash command failed. The command returned a non-zero exit code 126.
[2021-12-21 22:16:57,417] {local_task_job.py:154} INFO - Task exited with return code 1
[2021-12-21 22:16:57,428] {local_task_job.py:264} INFO - 0 downstream tasks scheduled from follow-on schedule check
